Workbook
Name LP: [1]Hoja1!$A$1:$F$38
Name LP_1: PLANILLA!$A$2:$AH$6

Sheet DB
A1: Id | B1: Nombre | C1: Numero | D1: Testructura | E1: Tauxiliar | F1: Tconductor | G1: Progresiva | H1: Cota | I1: Vertice | J1: Angulo | K1: VanoDelante | L1: Cantsoportes | M1: Tsoporte | N1: VanoPeso | O1: Vanoviento | P1: Retenidas | Q1: Contrapesos | R1: AmortiguadoresCP | S1: AmortiguadoresCG | T1: AmortiguadoresCS | U1: Tierra | V1: Cimentacion | W1: Comentarios | X1: Accesibilidad | Y1: Darboles | Z1: Tnormal | AA1: Trocoso | AB1: Thumedo | AC1: TkV | AD1: DesPosteMAD | AE1: DesPosteFierro | AF1: DesRetenida | AG1: DesVano | AH1: DesArmados | AI1: DesSecc | AJ1: MatExcedente | AK1: AbrazAislador
A2: 8 | B2: Derivacion 19 kV, 1x35 mm² AAAC - 1øMRT -Pto Libre-Pto-Yarina | C2: 0 | D2: DT-0 | E2: 0 | F2: AAAC-35 | G2: 0 | H2: 252 | I2: 0 | J2: 0° | K2: 86.38 | L2: 0 | M2: 13/200 | N2: 47.23 | O2: 43.19 | P2: - | Q2: 0 | R2: 0 | S2: 0 | T2: 0
A3: 8 | B3: Derivacion 19 kV, 1x35 mm² AAAC - 1øMRT -Pto Libre-Pto-Yarina | C3: 1 | D3: PSEC-0P | E3: 0 | F3: AAAC-35 | G3: 86.38 | H3: 250 | I3: P1 | J3: -4°52'16.80" | K3: 186.07 | L3: 1 | M3: 13/300 | N3: 125.33 | O3: 136.22 | P3: 1RI | Q3: 0 | R3: 0 | S3: 0 | T3: 0 | U3: PAT-1 | V3: CIM3
A4: 8 | B4: Derivacion 19 kV, 1x35 mm² AAAC - 1øMRT -Pto Libre-Pto-Yarina | C4: 2 | D4: PS1-0 | E4: 0 | F4: AAAC-35 | G4: 272.45 | H4: 251 | I4: 0 | J4: 0° | K4: 187.55 | L4: 1 | M4: 13/200 | N4: 189.24 | O4: 186.81 | P4: - | Q4: 0 | R4: 0 | S4: 0 | T4: 0 | U4: PAT-0 | V4: CIM3
A5: 8 | B5: Derivacion 19 kV, 1x35 mm² AAAC - 1øMRT -Pto Libre-Pto-Yarina | C5: 3 | D5: PS1-0 | E5: 0 | F5: AAAC-35 | G5: 459.99 | H5: 252 | I5: 0 | J5: 0° | K5: 186.87 | L5: 1 | M5: 13/200 | N5: 182.49 | O5: 187.21 | P5: - | Q5: 0 | R5: 0 | S5: 0 | T5: 0 | U5: PAT-0 | V5: CIM3
A6: 8 | B6: Derivacion 19 kV, 1x35 mm² AAAC - 1øMRT -Pto Libre-Pto-Yarina | C6: 4 | D6: PS1-0 | E6: 0 | F6: AAAC-35 | G6: 646.86 | H6: 254 | I6: 0 | J6: 0° | K6: 188.96 | L6: 1 | M6: 13/200 | N6: 203.31 | O6: 187.91 | P6: - | Q6: 0 | R6: 0 | S6: 0 | T6: 0 | U6: PAT-0 | V6: CIM3
A7: 8 | B7: Derivacion 19 kV, 1x35 mm² AAAC - 1øMRT -Pto Libre-Pto-Yarina | C7: 5 | D7: PS1-0 | E7: 0 | F7: AAAC-35 | G7: 835.82 | H7: 253 | I7: 0 | J7: 0° | K7: 180.34 | L7: 1 | M7: 13/200 | N7: 182.78 | O7: 184.65 | P7: - | Q7: 0 | R7: 0 | S7: 0 | T7: 0 | U7: PAT-0 | V7: CIM3
A8: 8 | B8: Derivacion 19 kV, 1x35 mm² AAAC - 1øMRT -Pto Libre-Pto-Yarina | C8: 6 | D8: PS1-0 | E8: 0 | F8: AAAC-35 | G8: 1016.16 | H8: 252.44 | I8: 0 | J8: 0° | K8: 197.47 | L8: 1 | M8: 13/200 | N8: 178.61 | O8: 188.9 | P8: - | Q8: 0 | R8: 0 | S8: 0 | T8: 0 | U8: PAT-0 | V8: CIM3
A9: 8 | B9: Derivacion 19 kV, 1x35 mm² AAAC - 1øMRT -Pto Libre-Pto-Yarina | C9: 7 | D9: PS1-0 | E9: 0 | F9: AAAC-35 | G9: 1213.63 | H9: 254 | I9: 0 | J9: 0° | K9: 182.42 | L9: 1 | M9: 13/200 | N9: 223.31 | O9: 189.94 | P9: - | Q9: 0 | R9: 0 | S9: 0 | T9: 0 | U9: PAT-0 | V9: CIM3
A10: 8 | B10: Derivacion 19 kV, 1x35 mm² AAAC - 1øMRT -Pto Libre-Pto-Yarina | C10: 8 | D10: PS1-0 | E10: 0 | F10: AAAC-35 | G10: 1396.05 | H10: 249 | I10: 0 | J10: 0° | K10: 183.39 | L10: 1 | M10: 13/200 | N10: 158 | O10: 182.91 | P10: - | Q10: 0 | R10: 0 | S10: 0 | T10: 0 | U10: PAT-0 | V10: CIM3
A11: 8 | B11: Derivacion 19 kV, 1x35 mm² AAAC - 1øMRT -Pto Libre-Pto-Yarina | C11: 9 | D11: PS1-0 | E11: 0 | F11: AAAC-35 | G11: 1579.44 | H11: 249 | I11: 0 | J11: 0° | K11: 172.09 | L11: 1 | M11: 13/200 | N11: 154.87 | O11: 177.74 | P11: - | Q11: 0 | R11: 0 | S11: 0 | T11: 0 | U11: PAT-0 | V11: CIM3
A12: 8 | B12: Derivacion 19 kV, 1x35 mm² AAAC - 1øMRT -Pto Libre-Pto-Yarina | C12: 10 | D12: PR3-0 | E12: 0 | F12: AAAC-35 | G12: 1751.52 | H12: 254 | I12: V | J12: -32°0'15.78" | K12: 152.8 | L12: 1 | M12: 13/300 | N12: 184.21 | O12: 162.45 | P12: 2RI | Q12: 0 | R12: 0 | S12: 0 | T12: 0 | U12: PAT-0 | V12: CIM3
A13: 8 | B13: Derivacion 19 kV, 1x35 mm² AAAC - 1øMRT -Pto Libre-Pto-Yarina | C13: 11 | D13: PS1-0 | E13: 0 | F13: AAAC-35 | G13: 1904.33 | H13: 253.88 | I13: 0 | J13: 0° | K13: 176.84 | L13: 1 | M13: 13/200 | N13: 151.45 | O13: 164.82 | P13: - | Q13: 0 | R13: 0 | S13: 0 | T13: 0 | U13: PAT-0 | V13: CIM3
A14: 8 | B14: Derivacion 19 kV, 1x35 mm² AAAC - 1øMRT -Pto Libre-Pto-Yarina | C14: 12 | D14: PS1-0 | E14: 0 | F14: AAAC-35 | G14: 2081.16 | H14: 256.91 | I14: 0 | J14: 0° | K14: 198.69 | L14: 1 | M14: 13/200 | N14: 178.17 | O14: 187.76 | P14: - | Q14: 0 | R14: 0 | S14: 0 | T14: 0 | U14: PAT-0 | V14: CIM3
A15: 8 | B15: Derivacion 19 kV, 1x35 mm² AAAC - 1øMRT -Pto Libre-Pto-Yarina | C15: 13 | D15: PS1-0 | E15: 0 | F15: AAAC-35 | G15: 2279.85 | H15: 262 | I15: 0 | J15: 0° | K15: 99.7 | L15: 1 | M15: 13/200 | N15: 150.74 | O15: 149.19 | P15: - | Q15: 0 | R15: 0 | S15: 0 | T15: 0 | U15: PAT-0 | V15: CIM3
A16: 8 | B16: Derivacion 19 kV, 1x35 mm² AAAC - 1øMRT -Pto Libre-Pto-Yarina | C16: 14 | D16: PR3-0 | E16: 0 | F16: AAAC-35 | G16: 2379.55 | H16: 267 | I16: V | J16: -38°39'35.31" | K16: 161.64 | L16: 1 | M16: 13/300 | N16: 163.15 | O16: 130.67 | P16: 2RI | Q16: 0 | R16: 0 | S16: 0 | T16: 0 | U16: PAT-0 | V16: CIM3
A17: 8 | B17: Derivacion 19 kV, 1x35 mm² AAAC - 1øMRT -Pto Libre-Pto-Yarina | C17: 15 | D17: PS1-0 | E17: 0 | F17: AAAC-35 | G17: 2541.19 | H17: 264.97 | I17: 0 | J17: 0° | K17: 199.36 | L17: 1 | M17: 13/200 | N17: 192.32 | O17: 180.5 | P17: - | Q17: 0 | R17: 0 | S17: 0 | T17: 0 | U17: PAT-0 | V17: CIM3
A18: 8 | B18: Derivacion 19 kV, 1x35 mm² AAAC - 1øMRT -Pto Libre-Pto-Yarina | C18: 16 | D18: PS1-0 | E18: 0 | F18: AAAC-35 | G18: 2740.55 | H18: 261.01 | I18: 0 | J18: 0° | K18: 234.76 | L18: 1 | M18: 13/200 | N18: 198.25 | O18: 217.06 | P18: - | Q18: 0 | R18: 0 | S18: 0 | T18: 0 | U18: PAT-0 | V18: CIM3
A19: 8 | B19: Derivacion 19 kV, 1x35 mm² AAAC - 1øMRT -Pto Libre-Pto-Yarina | C19: 17 | D19: PS1-0 | E19: 0 | F19: AAAC-35 | G19: 2975.31 | H19: 260.93 | I19: 0 | J19: 0° | K19: 188.9 | L19: 1 | M19: 13/200 | N19: 196.38 | O19: 211.83 | P19: - | Q19: 0 | R19: 0 | S19: 0 | T19: 0 | U19: PAT-0 | V19: CIM3
A20: 8 | B20: Derivacion 19 kV, 1x35 mm² AAAC - 1øMRT -Pto Libre-Pto-Yarina | C20: 18 | D20: PA1-0 | E20: 0 | F20: AAAC-35 | G20: 3164.21 | H20: 264 | I20: V | J20: -8°26'40.14" | K20: 249.33 | L20: 1 | M20: 13/200 | N20: 295.98 | O20: 219.11 | P20: 1RI | Q20: 0 | R20: 0 | S20: 0 | T20: 0 | U20: PAT-0 | V20: CIM3
A21: 8 | B21: Derivacion 19 kV, 1x35 mm² AAAC - 1øMRT -Pto Libre-Pto-Yarina | C21: 19 | D21: PS1-0 | E21: 0 | F21: AAAC-35 | G21: 3413.54 | H21: 251.01 | I21: 0 | J21: 0° | K21: 190.57 | L21: 1 | M21: 13/200 | N21: 174.26 | O21: 219.95 | P21: - | Q21: 0 | R21: 0 | S21: 0 | T21: 0 | U21: PAT-0 | V21: CIM3
A22: 8 | B22: Derivacion 19 kV, 1x35 mm² AAAC - 1øMRT -Pto Libre-Pto-Yarina | C22: 20 | D22: PA1-0 | E22: 0 | F22: AAAC-35 | G22: 3604.1 | H22: 248 | I22: FLP | J22: -25°20'11.83" | K22: 180.05 | L22: 1 | M22: 13/200 | N22: 155.86 | O22: 185.31 | P22: 1RI | Q22: 0 | R22: 0 | S22: 0 | T22: 0 | U22: PAT-0 | V22: CIM3
A23: 8 | B23: Derivacion 19 kV, 1x35 mm² AAAC - 1øMRT -Pto Libre-Pto-Yarina | C23: 21 | D23: PS1-0 | E23: 0 | F23: AAAC-35 | G23: 3784.16 | H23: 251 | I23: 0 | J23: 0° | K23: 135.27 | L23: 1 | M23: 13/200 | N23: 175.98 | O23: 157.66 | P23: - | Q23: 0 | R23: 0 | S23: 0 | T23: 0 | U23: PAT-0 | V23: CIM3
A24: 8 | B24: Derivacion 19 kV, 1x35 mm² AAAC - 1øMRT -Pto Libre-Pto-Yarina | C24: 22 | D24: PTV-0 | E24: 0 | F24: AAAC-35 | G24: 3919.43 | H24: 251 | I24: E22 | J24: 0° | K24: 0 | L24: 1 | M24: 13/300 | N24: 64.86 | O24: 67.64 | P24: 1RI | Q24: 0 | R24: 0 | S24: 0 | T24: 0 | U24: PAT-0 | V24: CIM3
A25: 9 | B25: Derivación 19 kV, 1x35 mm² AAAC - 1øMRT - Nazareth | C25: 0 | D25: DT-0 | F25: AAAC-35 | G25: 0 | H25: 267 | I25: Po | J25: 0° | K25: 52.64 | L25: 1 | M25: 13/200 | N25: 25.58 | O25: 26.32 | P25: - | Q25: 0 | R25: 0 | S25: 0 | T25: 0
A26: 9 | B26: Derivación 19 kV, 1x35 mm² AAAC - 1øMRT - Nazareth | C26: 1 | D26: PSEC-0P | F26: AAAC-35 | G26: 52.64 | H26: 266 | I26: V1 | J26: 34°55'37.99" | K26: 117.97 | L26: 1 | M26: 13/300 | N26: 96.94 | O26: 85.31 | P26: 1RI | Q26: 0 | R26: 0 | S26: 0 | T26: 0 | U26: PAT-1 | V26: CIM3
A27: 9 | B27: Derivación 19 kV, 1x35 mm² AAAC - 1øMRT - Nazareth | C27: 2 | D27: PR3-0 | F27: AAAC-35 | G27: 170.62 | H27: 264 | I27: P2 | J27: 0°0'0.46" | K27: 456.04 | L27: 1 | M27: 13/300 | N27: 396.81 | O27: 287.01 | P27: 2RI | Q27: 0 | R27: 2 | S27: 0 | T27: 0 | U27: PAT-0 | V27: CIM3
A28: 9 | B28: Derivación 19 kV, 1x35 mm² AAAC - 1øMRT - Nazareth | C28: 3 | D28: PR3-0 | F28: AAAC-35 | G28: 626.66 | H28: 231 | I28: V2 | J28: -5°20'28.34" | K28: 200.53 | L28: 1 | M28: 13m/C6 | N28: 193.42 | O28: 328.28 | P28: 2RI | Q28: 0 | R28: 0 | S28: 0 | T28: 0 | U28: PAT-0 | V28: CIM1
A29: 9 | B29: Derivación 19 kV, 1x35 mm² AAAC - 1øMRT - Nazareth | C29: 4 | D29: PTV-0 | F29: AAAC-35 | G29: 827.19 | H29: 234.5 | I29: FLP | J29: 0° | K29: 0 | L29: 1 | M29: 13m/C6 | N29: 117.81 | O29: 100.27 | P29: 1RI | Q29: 0 | R29: 0 | S29: 0 | T29: 0 | U29: PAT-0 | V29: CIM1
A30: 10 | B30: Derivación 19 kV, 1x35 mm² AAAC - 1øMRT - Shanshuya | C30: 0 | D30: DS-0A | F30: AAAC-35 | G30: 0 | H30: 267 | J30: 0° | K30: 52.47 | L30: 0 | M30: 13/200 | N30: 13.8 | O30: 26.23 | P30: - | Q30: 0 | R30: 0 | S30: 0 | T30: 0
A31: 10 | B31: Derivación 19 kV, 1x35 mm² AAAC - 1øMRT - Shanshuya | C31: 1 | D31: PSEC-0PA | F31: AAAC-35 | G31: 52.47 | H31: 268 | I31: V | J31: 19°17'10.30" | K31: 185.19 | L31: 1 | M31: 13/300 | N31: 140.07 | O31: 118.83 | P31: 1RI | Q31: 0 | R31: 0 | S31: 0 | T31: 0 | U31: PAT-1 | V31: CIM3
A32: 10 | B32: Derivación 19 kV, 1x35 mm² AAAC - 1øMRT - Shanshuya | C32: 2 | D32: PS1-0 | F32: AAAC-35 | G32: 237.66 | H32: 265.97 | J32: 0° | K32: 110.85 | L32: 1 | M32: 13/200 | N32: 114.67 | O32: 148.02 | P32: - | Q32: 0 | R32: 0 | S32: 0 | T32: 0 | U32: PAT-0 | V32: CIM3
A33: 10 | B33: Derivación 19 kV, 1x35 mm² AAAC - 1øMRT - Shanshuya | C33: 3 | D33: PS1-0 | F33: AAAC-35 | G33: 348.52 | H33: 269.99 | J33: 0° | K33: 170.04 | L33: 1 | M33: 13/200 | N33: 198.31 | O33: 140.45 | P33: - | Q33: 0 | R33: 0 | S33: 0 | T33: 0 | U33: PAT-0 | V33: CIM3
A34: 10 | B34: Derivación 19 kV, 1x35 mm² AAAC - 1øMRT - Shanshuya | C34: 4 | D34: PR3-0 | F34: AAAC-35 | G34: 518.56 | H34: 265 | J34: 0° | K34: 590.7 | L34: 1 | M34: 13/300 | N34: 343.77 | O34: 380.37 | P34: 2RI | Q34: 0 | R34: 2 | S34: 0 | T34: 0 | U34: PAT-0 | V34: CIM3
A35: 10 | B35: Derivación 19 kV, 1x35 mm² AAAC - 1øMRT - Shanshuya | C35: 5 | D35: PTV-0 | F35: AAAC-35 | G35: 1109.26 | H35: 267 | I35: FLP | J35: 0° | K35: 0 | L35: 1 | M35: 13m/C6 | N35: 301.98 | O35: 295.35 | P35: 1RI | Q35: 0 | R35: 0 | S35: 0 | T35: 0 | U35: PAT-0 | V35: CIM1
A36: 11 | B36: Derivación 19 kV, 1x35 mm² AAAC - 1øMRT -Vista Alegre | C36: 0 | D36: DS-0A | F36: AAAC-35 | G36: 0 | H36: 256 | J36: 0° | K36: 48.73 | L36: 0 | M36: 13/300 | N36: 29.52 | O36: 24.36 | P36: - | Q36: 0 | R36: 0 | S36: 0 | T36: 0
A37: 11 | B37: Derivación 19 kV, 1x35 mm² AAAC - 1øMRT -Vista Alegre | C37: 1 | D37: TS-0 | F37: AAAC-35 | G37: 48.73 | H37: 254 | I37: P1 | J37: 73°40'13.91" | K37: 126.44 | L37: 1 | M37: 13/300 | N37: 50.91 | O37: 87.59 | P37: 1RI | Q37: 0 | R37: 0 | S37: 0 | T37: 0 | U37: PAT-0 | V37: CIM3
A38: 11 | B38: Derivación 19 kV, 1x35 mm² AAAC - 1øMRT -Vista Alegre | C38: 2 | D38: PS1-0 | F38: AAAC-35 | G38: 175.17 | H38: 260 | J38: 0° | K38: 196.15 | L38: 1 | M38: 13m/C6 | N38: 178.47 | O38: 161.3 | P38: - | Q38: 0 | R38: 0 | S38: 0 | T38: 0 | U38: PAT-0 | V38: CIM1
A39: 11 | B39: Derivación 19 kV, 1x35 mm² AAAC - 1øMRT -Vista Alegre | C39: 3 | D39: PA1-0 | F39: AAAC-35 | G39: 371.32 | H39: 263 | I39: V1 | J39: 22°9'44.64" | K39: 127.39 | L39: 1 | M39: 13m/C6 | N39: 192.94 | O39: 161.77 | P39: 1RI | Q39: 0 | R39: 0 | S39: 0 | T39: 0 | U39: PAT-0 | V39: CIM1
A40: 11 | B40: Derivación 19 kV, 1x35 mm² AAAC - 1øMRT -Vista Alegre | C40: 4 | D40: PS1-0 | F40: AAAC-35 | G40: 498.71 | H40: 259.97 | J40: 0° | K40: 170.35 | L40: 1 | M40: 13m/C6 | N40: 124.28 | O40: 148.87 | P40: - | Q40: 0 | R40: 0 | S40: 0 | T40: 0 | U40: PAT-0 | V40: CIM1
...

Sheet PLANILLA
A1: EST. Nº | B1: Armado | C1: Principal | D1: Auxiliar | E1: Fusible Jgo | F1: Progresiva | G1: Cota | H1: Vano Peso m | I1: Vano Viento m | J1: Vértice | K1: Angulo | L1: Cantidad | M1: Longitud | N1: Material | O1: codigo | P1: Tipo de Terreno (%) | S1: Vano Adelante | T1: Sección | U1: Nº de | V1: Amortiguadores | W1: RI-A | X1: RV-A | Y1: RYI | Z1: RYV | AA1: Tipo | AB1: Fundación | AC1: Tipo Aislador Pin | AD1: Tipo Aislador Suspensión | AE1: Accesibilidad | AF1: Despeje de Arboles % | AG1: Abrazadera Para Aislador de Suspensión | AH1: Comentarios
A2: =+DB!C2 -> 0 | B2: =+DB!D2 -> DT-0 | C2: =+DB!E2 -> 0 | D2: =+IF(B2="PSEC-0PA","K",0) -> 0 | E2: =+DB!G2 -> 0 | F2: =+DB!H2 -> 252 | G2: =+DB!N2 -> 47.23 | H2: =+DB!O2 -> 43.19 | I2: =+DB!I2 -> 0 | J2: =+DB!J2 -> 0° | K2: =+DB!L2 -> 0 | L2: =+LEFT(N2,2) -> 13 | M2: =+IF(LEFT(DB!M2,3)="13/","CAC","MAD") -> CAC | N2: =+RIGHT(DB!M2,6) -> 13/200 | O2: 95 | P2: 5 | Q2: =+DB!AB2 -> 0 | R2: =+DB!K2 -> 86.38 | S2: =+DB!F2 -> AAAC-35 | T2: =+IF(DB!F2="AAAC-35",1,3) -> 1 | U2: =+DB!R2 -> 0 | V2: =+IF(DB!P2="1RI",1,0)+IF(DB!P2="2RI",2,0) -> 0 | W2: =+IF(DB!P2="1RV",1,0)+IF(DB!P2="2RV",2,0) -> 0 | X2: =+IF(DB!P2="RYI",1,0) -> 0 | Y2: =+IF(DB!P2="RYV",1,0) -> 0 | Z2: =+DB!U2 -> 0 | AA2: =+IF(DB!F2="AAAC-35",19.5,33) -> 19.5 | AB2: =+DB!V2 -> 0 | AC2: =+IF(F2>1675,"56-5","56-4") -> 56-4 | AD2: 'IPB-36' | AE2: =+DB!X2 -> 0 | AF2: =+DB!Y2 -> 0 | AG2: =+DB!AK2 -> 0
A3: =+DB!C3 -> 1 | B3: =+DB!D3 -> PSEC-0P | C3: =+DB!E3 -> 0 | D3: =+IF(B3="PSEC-0PA","K",0) -> 0 | E3: =+DB!G3 -> 86.38 | F3: =+DB!H3 -> 250 | G3: =+DB!N3 -> 125.33 | H3: =+DB!O3 -> 136.22 | I3: =+DB!I3 -> P1 | J3: =+DB!J3 -> -4°52'16.80" | K3: =+DB!L3 -> 1 | L3: =+LEFT(N3,2) -> 13 | M3: =+IF(LEFT(DB!M3,3)="13/","CAC","MAD") -> CAC | N3: =+RIGHT(DB!M3,6) -> 13/300 | O3: 95 | P3: 5 | Q3: =+DB!AB3 -> 0 | R3: =+DB!K3 -> 186.07 | S3: =+DB!F3 -> AAAC-35 | T3: =+IF(DB!F3="AAAC-35",1,3) -> 1 | U3: =+DB!R3 -> 0 | V3: =+IF(DB!P3="1RI",1,0)+IF(DB!P3="2RI",2,0) -> 1 | W3: =+IF(DB!P3="1RV",1,0)+IF(DB!P3="2RV",2,0) -> 0 | X3: =+IF(DB!P3="RYI",1,0) -> 0 | Y3: =+IF(DB!P3="RYV",1,0) -> 0 | Z3: =+DB!U3 -> PAT-1 | AA3: =+IF(DB!F3="AAAC-35",19.5,33) -> 19.5 | AB3: =+DB!V3 -> CIM3 | AC3: =+IF(F3>1675,"56-5","56-4") -> 56-4 | AD3: 'IPB-36' | AE3: =+DB!X3 -> 0 | AF3: =+DB!Y3 -> 0 | AG3: =+DB!AK3 -> 0
A4: =+DB!C4 -> 2 | B4: =+DB!D4 -> PS1-0 | C4: =+DB!E4 -> 0 | D4: =+IF(B4="PSEC-0PA","K",0) -> 0 | E4: =+DB!G4 -> 272.45 | F4: =+DB!H4 -> 251 | G4: =+DB!N4 -> 189.24 | H4: =+DB!O4 -> 186.81 | I4: =+DB!I4 -> 0 | J4: =+DB!J4 -> 0° | K4: =+DB!L4 -> 1 | L4: =+LEFT(N4,2) -> 13 | M4: =+IF(LEFT(DB!M4,3)="13/","CAC","MAD") -> CAC | N4: =+RIGHT(DB!M4,6) -> 13/200 | O4: 95 | P4: 5 | Q4: =+DB!AB4 -> 0 | R4: =+DB!K4 -> 187.55 | S4: =+DB!F4 -> AAAC-35 | T4: =+IF(DB!F4="AAAC-35",1,3) -> 1 | U4: =+DB!R4 -> 0 | V4: =+IF(DB!P4="1RI",1,0)+IF(DB!P4="2RI",2,0) -> 0 | W4: =+IF(DB!P4="1RV",1,0)+IF(DB!P4="2RV",2,0) -> 0 | X4: =+IF(DB!P4="RYI",1,0) -> 0 | Y4: =+IF(DB!P4="RYV",1,0) -> 0 | Z4: =+DB!U4 -> PAT-0 | AA4: =+IF(DB!F4="AAAC-35",19.5,33) -> 19.5 | AB4: =+DB!V4 -> CIM3 | AC4: =+IF(F4>1675,"56-5","56-4") -> 56-4 | AD4: 'IPB-36' | AE4: =+DB!X4 -> 0 | AF4: =+DB!Y4 -> 0 | AG4: =+DB!AK4 -> 0
A5: =+DB!C5 -> 3 | B5: =+DB!D5 -> PS1-0 | C5: =+DB!E5 -> 0 | D5: =+IF(B5="PSEC-0PA","K",0) -> 0 | E5: =+DB!G5 -> 459.99 | F5: =+DB!H5 -> 252 | G5: =+DB!N5 -> 182.49 | H5: =+DB!O5 -> 187.21 | I5: =+DB!I5 -> 0 | J5: =+DB!J5 -> 0° | K5: =+DB!L5 -> 1 | L5: =+LEFT(N5,2) -> 13 | M5: =+IF(LEFT(DB!M5,3)="13/","CAC","MAD") -> CAC | N5: =+RIGHT(DB!M5,6) -> 13/200 | O5: 95 | P5: 5 | Q5: =+DB!AB5 -> 0 | R5: =+DB!K5 -> 186.87 | S5: =+DB!F5 -> AAAC-35 | T5: =+IF(DB!F5="AAAC-35",1,3) -> 1 | U5: =+DB!R5 -> 0 | V5: =+IF(DB!P5="1RI",1,0)+IF(DB!P5="2RI",2,0) -> 0 | W5: =+IF(DB!P5="1RV",1,0)+IF(DB!P5="2RV",2,0) -> 0 | X5: =+IF(DB!P5="RYI",1,0) -> 0 | Y5: =+IF(DB!P5="RYV",1,0) -> 0 | Z5: =+DB!U5 -> PAT-0 | AA5: =+IF(DB!F5="AAAC-35",19.5,33) -> 19.5 | AB5: =+DB!V5 -> CIM3 | AC5: =+IF(F5>1675,"56-5","56-4") -> 56-4 | AD5: 'IPB-36' | AE5: =+DB!X5 -> 0 | AF5: =+DB!Y5 -> 0 | AG5: =+DB!AK5 -> 0
A6: =+DB!C6 -> 4 | B6: =+DB!D6 -> PS1-0 | C6: =+DB!E6 -> 0 | D6: =+IF(B6="PSEC-0PA","K",0) -> 0 | E6: =+DB!G6 -> 646.86 | F6: =+DB!H6 -> 254 | G6: =+DB!N6 -> 203.31 | H6: =+DB!O6 -> 187.91 | I6: =+DB!I6 -> 0 | J6: =+DB!J6 -> 0° | K6: =+DB!L6 -> 1 | L6: =+LEFT(N6,2) -> 13 | M6: =+IF(LEFT(DB!M6,3)="13/","CAC","MAD") -> CAC | N6: =+RIGHT(DB!M6,6) -> 13/200 | O6: 95 | P6: 5 | Q6: =+DB!AB6 -> 0 | R6: =+DB!K6 -> 188.96 | S6: =+DB!F6 -> AAAC-35 | T6: =+IF(DB!F6="AAAC-35",1,3) -> 1 | U6: =+DB!R6 -> 0 | V6: =+IF(DB!P6="1RI",1,0)+IF(DB!P6="2RI",2,0) -> 0 | W6: =+IF(DB!P6="1RV",1,0)+IF(DB!P6="2RV",2,0) -> 0 | X6: =+IF(DB!P6="RYI",1,0) -> 0 | Y6: =+IF(DB!P6="RYV",1,0) -> 0 | Z6: =+DB!U6 -> PAT-0 | AA6: =+IF(DB!F6="AAAC-35",19.5,33) -> 19.5 | AB6: =+DB!V6 -> CIM3 | AC6: =+IF(F6>1675,"56-5","56-4") -> 56-4 | AD6: 'IPB-36' | AE6: =+DB!X6 -> 0 | AF6: =+DB!Y6 -> 0 | AG6: =+DB!AK6 -> 0
A7: =+DB!C7 -> 5 | B7: =+DB!D7 -> PS1-0 | C7: =+DB!E7 -> 0 | D7: =+IF(B7="PSEC-0PA","K",0) -> 0 | E7: =+DB!G7 -> 835.82 | F7: =+DB!H7 -> 253 | G7: =+DB!N7 -> 182.78 | H7: =+DB!O7 -> 184.65 | I7: =+DB!I7 -> 0 | J7: =+DB!J7 -> 0° | K7: =+DB!L7 -> 1 | L7: =+LEFT(N7,2) -> 13 | M7: =+IF(LEFT(DB!M7,3)="13/","CAC","MAD") -> CAC | N7: =+RIGHT(DB!M7,6) -> 13/200 | O7: 95 | P7: 5 | Q7: =+DB!AB7 -> 0 | R7: =+DB!K7 -> 180.34 | S7: =+DB!F7 -> AAAC-35 | T7: =+IF(DB!F7="AAAC-35",1,3) -> 1 | U7: =+DB!R7 -> 0 | V7: =+IF(DB!P7="1RI",1,0)+IF(DB!P7="2RI",2,0) -> 0 | W7: =+IF(DB!P7="1RV",1,0)+IF(DB!P7="2RV",2,0) -> 0 | X7: =+IF(DB!P7="RYI",1,0) -> 0 | Y7: =+IF(DB!P7="RYV",1,0) -> 0 | Z7: =+DB!U7 -> PAT-0 | AA7: =+IF(DB!F7="AAAC-35",19.5,33) -> 19.5 | AB7: =+DB!V7 -> CIM3 | AC7: =+IF(F7>1675,"56-5","56-4") -> 56-4 | AD7: 'IPB-36' | AE7: =+DB!X7 -> 0 | AF7: =+DB!Y7 -> 0 | AG7: =+DB!AK7 -> 0
A8: =+DB!C8 -> 6 | B8: =+DB!D8 -> PS1-0 | C8: =+DB!E8 -> 0 | D8: =+IF(B8="PSEC-0PA","K",0) -> 0 | E8: =+DB!G8 -> 1016.16 | F8: =+DB!H8 -> 252.44 | G8: =+DB!N8 -> 178.61 | H8: =+DB!O8 -> 188.9 | I8: =+DB!I8 -> 0 | J8: =+DB!J8 -> 0° | K8: =+DB!L8 -> 1 | L8: =+LEFT(N8,2) -> 13 | M8: =+IF(LEFT(DB!M8,3)="13/","CAC","MAD") -> CAC | N8: =+RIGHT(DB!M8,6) -> 13/200 | O8: 95 | P8: 5 | Q8: =+DB!AB8 -> 0 | R8: =+DB!K8 -> 197.47 | S8: =+DB!F8 -> AAAC-35 | T8: =+IF(DB!F8="AAAC-35",1,3) -> 1 | U8: =+DB!R8 -> 0 | V8: =+IF(DB!P8="1RI",1,0)+IF(DB!P8="2RI",2,0) -> 0 | W8: =+IF(DB!P8="1RV",1,0)+IF(DB!P8="2RV",2,0) -> 0 | X8: =+IF(DB!P8="RYI",1,0) -> 0 | Y8: =+IF(DB!P8="RYV",1,0) -> 0 | Z8: =+DB!U8 -> PAT-0 | AA8: =+IF(DB!F8="AAAC-35",19.5,33) -> 19.5 | AB8: =+DB!V8 -> CIM3 | AC8: =+IF(F8>1675,"56-5","56-4") -> 56-4 | AD8: 'IPB-36' | AE8: =+DB!X8 -> 0 | AF8: =+DB!Y8 -> 0 | AG8: =+DB!AK8 -> 0
A9: =+DB!C9 -> 7 | B9: =+DB!D9 -> PS1-0 | C9: =+DB!E9 -> 0 | D9: =+IF(B9="PSEC-0PA","K",0) -> 0 | E9: =+DB!G9 -> 1213.63 | F9: =+DB!H9 -> 254 | G9: =+DB!N9 -> 223.31 | H9: =+DB!O9 -> 189.94 | I9: =+DB!I9 -> 0 | J9: =+DB!J9 -> 0° | K9: =+DB!L9 -> 1 | L9: =+LEFT(N9,2) -> 13 | M9: =+IF(LEFT(DB!M9,3)="13/","CAC","MAD") -> CAC | N9: =+RIGHT(DB!M9,6) -> 13/200 | O9: 95 | P9: 5 | Q9: =+DB!AB9 -> 0 | R9: =+DB!K9 -> 182.42 | S9: =+DB!F9 -> AAAC-35 | T9: =+IF(DB!F9="AAAC-35",1,3) -> 1 | U9: =+DB!R9 -> 0 | V9: =+IF(DB!P9="1RI",1,0)+IF(DB!P9="2RI",2,0) -> 0 | W9: =+IF(DB!P9="1RV",1,0)+IF(DB!P9="2RV",2,0) -> 0 | X9: =+IF(DB!P9="RYI",1,0) -> 0 | Y9: =+IF(DB!P9="RYV",1,0) -> 0 | Z9: =+DB!U9 -> PAT-0 | AA9: =+IF(DB!F9="AAAC-35",19.5,33) -> 19.5 | AB9: =+DB!V9 -> CIM3 | AC9: =+IF(F9>1675,"56-5","56-4") -> 56-4 | AD9: 'IPB-36' | AE9: =+DB!X9 -> 0 | AF9: =+DB!Y9 -> 0 | AG9: =+DB!AK9 -> 0
A10: =+DB!C10 -> 8 | B10: =+DB!D10 -> PS1-0 | C10: =+DB!E10 -> 0 | D10: =+IF(B10="PSEC-0PA","K",0) -> 0 | E10: =+DB!G10 -> 1396.05 | F10: =+DB!H10 -> 249 | G10: =+DB!N10 -> 158 | H10: =+DB!O10 -> 182.91 | I10: =+DB!I10 -> 0 | J10: =+DB!J10 -> 0° | K10: =+DB!L10 -> 1 | L10: =+LEFT(N10,2) -> 13 | M10: =+IF(LEFT(DB!M10,3)="13/","CAC","MAD") -> CAC | N10: =+RIGHT(DB!M10,6) -> 13/200 | O10: 95 | P10: 5 | Q10: =+DB!AB10 -> 0 | R10: =+DB!K10 -> 183.39 | S10: =+DB!F10 -> AAAC-35 | T10: =+IF(DB!F10="AAAC-35",1,3) -> 1 | U10: =+DB!R10 -> 0 | V10: =+IF(DB!P10="1RI",1,0)+IF(DB!P10="2RI",2,0) -> 0 | W10: =+IF(DB!P10="1RV",1,0)+IF(DB!P10="2RV",2,0) -> 0 | X10: =+IF(DB!P10="RYI",1,0) -> 0 | Y10: =+IF(DB!P10="RYV",1,0) -> 0 | Z10: =+DB!U10 -> PAT-0 | AA10: =+IF(DB!F10="AAAC-35",19.5,33) -> 19.5 | AB10: =+DB!V10 -> CIM3 | AC10: =+IF(F10>1675,"56-5","56-4") -> 56-4 | AD10: 'IPB-36' | AE10: =+DB!X10 -> 0 | AF10: =+DB!Y10 -> 0 | AG10: =+DB!AK10 -> 0
A11: =+DB!C11 -> 9 | B11: =+DB!D11 -> PS1-0 | C11: =+DB!E11 -> 0 | D11: =+IF(B11="PSEC-0PA","K",0) -> 0 | E11: =+DB!G11 -> 1579.44 | F11: =+DB!H11 -> 249 | G11: =+DB!N11 -> 154.87 | H11: =+DB!O11 -> 177.74 | I11: =+DB!I11 -> 0 | J11: =+DB!J11 -> 0° | K11: =+DB!L11 -> 1 | L11: =+LEFT(N11,2) -> 13 | M11: =+IF(LEFT(DB!M11,3)="13/","CAC","MAD") -> CAC | N11: =+RIGHT(DB!M11,6) -> 13/200 | O11: 95 | P11: 5 | Q11: =+DB!AB11 -> 0 | R11: =+DB!K11 -> 172.09 | S11: =+DB!F11 -> AAAC-35 | T11: =+IF(DB!F11="AAAC-35",1,3) -> 1 | U11: =+DB!R11 -> 0 | V11: =+IF(DB!P11="1RI",1,0)+IF(DB!P11="2RI",2,0) -> 0 | W11: =+IF(DB!P11="1RV",1,0)+IF(DB!P11="2RV",2,0) -> 0 | X11: =+IF(DB!P11="RYI",1,0) -> 0 | Y11: =+IF(DB!P11="RYV",1,0) -> 0 | Z11: =+DB!U11 -> PAT-0 | AA11: =+IF(DB!F11="AAAC-35",19.5,33) -> 19.5 | AB11: =+DB!V11 -> CIM3 | AC11: =+IF(F11>1675,"56-5","56-4") -> 56-4 | AD11: 'IPB-36' | AE11: =+DB!X11 -> 0 | AF11: =+DB!Y11 -> 0 | AG11: =+DB!AK11 -> 0
A12: =+DB!C12 -> 10 | B12: =+DB!D12 -> PR3-0 | C12: =+DB!E12 -> 0 | D12: =+IF(B12="PSEC-0PA","K",0) -> 0 | E12: =+DB!G12 -> 1751.52 | F12: =+DB!H12 -> 254 | G12: =+DB!N12 -> 184.21 | H12: =+DB!O12 -> 162.45 | I12: =+DB!I12 -> V | J12: =+DB!J12 -> -32°0'15.78" | K12: =+DB!L12 -> 1 | L12: =+LEFT(N12,2) -> 13 | M12: =+IF(LEFT(DB!M12,3)="13/","CAC","MAD") -> CAC | N12: =+RIGHT(DB!M12,6) -> 13/300 | O12: 95 | P12: 5 | Q12: =+DB!AB12 -> 0 | R12: =+DB!K12 -> 152.8 | S12: =+DB!F12 -> AAAC-35 | T12: =+IF(DB!F12="AAAC-35",1,3) -> 1 | U12: =+DB!R12 -> 0 | V12: =+IF(DB!P12="1RI",1,0)+IF(DB!P12="2RI",2,0) -> 2 | W12: =+IF(DB!P12="1RV",1,0)+IF(DB!P12="2RV",2,0) -> 0 | X12: =+IF(DB!P12="RYI",1,0) -> 0 | Y12: =+IF(DB!P12="RYV",1,0) -> 0 | Z12: =+DB!U12 -> PAT-0 | AA12: =+IF(DB!F12="AAAC-35",19.5,33) -> 19.5 | AB12: =+DB!V12 -> CIM3 | AC12: =+IF(F12>1675,"56-5","56-4") -> 56-4 | AD12: 'IPB-36' | AE12: =+DB!X12 -> 0 | AF12: =+DB!Y12 -> 0 | AG12: =+DB!AK12 -> 0
A13: =+DB!C13 -> 11 | B13: =+DB!D13 -> PS1-0 | C13: =+DB!E13 -> 0 | D13: =+IF(B13="PSEC-0PA","K",0) -> 0 | E13: =+DB!G13 -> 1904.33 | F13: =+DB!H13 -> 253.88 | G13: =+DB!N13 -> 151.45 | H13: =+DB!O13 -> 164.82 | I13: =+DB!I13 -> 0 | J13: =+DB!J13 -> 0° | K13: =+DB!L13 -> 1 | L13: =+LEFT(N13,2) -> 13 | M13: =+IF(LEFT(DB!M13,3)="13/","CAC","MAD") -> CAC | N13: =+RIGHT(DB!M13,6) -> 13/200 | O13: 95 | P13: 5 | Q13: =+DB!AB13 -> 0 | R13: =+DB!K13 -> 176.84 | S13: =+DB!F13 -> AAAC-35 | T13: =+IF(DB!F13="AAAC-35",1,3) -> 1 | U13: =+DB!R13 -> 0 | V13: =+IF(DB!P13="1RI",1,0)+IF(DB!P13="2RI",2,0) -> 0 | W13: =+IF(DB!P13="1RV",1,0)+IF(DB!P13="2RV",2,0) -> 0 | X13: =+IF(DB!P13="RYI",1,0) -> 0 | Y13: =+IF(DB!P13="RYV",1,0) -> 0 | Z13: =+DB!U13 -> PAT-0 | AA13: =+IF(DB!F13="AAAC-35",19.5,33) -> 19.5 | AB13: =+DB!V13 -> CIM3 | AC13: =+IF(F13>1675,"56-5","56-4") -> 56-4 | AD13: 'IPB-36' | AE13: =+DB!X13 -> 0 | AF13: =+DB!Y13 -> 0 | AG13: =+DB!AK13 -> 0
... A879: =+DB!C879 -> 0 | B879: =+DB!D879 -> 0 | C879: =+DB!E879 -> 0 | D879: =+IF(B879="PSEC-0PA","K",0) -> 0 | E879: =+DB!G879 -> 0 | F879: =+DB!H879 -> 0 | G879: =+DB!N879 -> 0 | H879: =+DB!O879 -> 0 | I879: =+DB!I879 -> 0 | J879: =+DB!J879 -> 0 | K879: =+DB!L879 -> 0 | L879: =+LEFT(N879,2) | M879: =+IF(LEFT(DB!M879,3)="13/","CAC","MAD") -> MAD | N879: =+RIGHT(DB!M879,6) | O879: 95 | P879: 5 | Q879: =+DB!AB879 -> 0 | R879: =+DB!K879 -> 0 | S879: =+DB!F879 -> 0 | T879: =+IF(DB!F879="AAAC-35",1,3) -> 3 | U879: =+DB!R879 -> 0 | V879: =+IF(DB!P879="1RI",1,0)+IF(DB!P879="2RI",2,0) -> 0 | W879: =+IF(DB!P879="1RV",1,0)+IF(DB!P879="2RV",2,0) -> 0 | X879: =+IF(DB!P879="RYI",1,0) -> 0 | Y879: =+IF(DB!P879="RYV",1,0) -> 0 | Z879: =+DB!U879 -> 0 | AA879: =+IF(DB!F879="AAAC-35",19.5,33) -> 33 | AB879: =+DB!V879 -> 0 | AC879: =+IF(F879>1675,"56-5","56-4") -> 56-4 | AD879: 'IPB-36' | AE879: =+DB!X879 -> 0 | AF879: =+DB!Y879 -> 0 | AG879: =+DB!AK879 -> 0
